Workbook
Name XDO_?ASSET_TYPE_DEBT?: 'TRUSTMF Banking & PSU Fund'!$B$7:$B$31
Name XDO_?ASSET_TYPE_DEBT?1?: 'TRUSTMF Liquid Fund'!$B$6:$B$7
Name XDO_?ASSET_TYPE_DEBT?2?: 'TRUSTMF Liquid Fund'!$B$6:$B$9
Name XDO_?ASSET_TYPE_DEBT?3?: 'TRUSTMF Liquid Fund'!$B$6:$B$10
Name XDO_?ASSET_TYPE_DEBT?4?: 'TRUSTMF Money Market Fund'!$B$6:$B$7
Name XDO_?ASSET_TYPE_DEBT?4?: 'TRUSTMF Overnight Fund'!$B$6:$B$7
Name XDO_?ASSET_TYPE_DEBT?4?: 'TRUSTMF Short Duration Fund'!$B$6:$B$11
Name XDO_?ASSET_TYPE_DEBT?5?: 'TRUSTMF Money Market Fund'!$B$6:$B$9
Name XDO_?ASSET_TYPE_DEBT?5?: 'TRUSTMF Overnight Fund'!$B$6:$B$9
Name XDO_?ASSET_TYPE_DEBT?5?: 'TRUSTMF Short Duration Fund'!$B$6:$B$20
Name XDO_?ASSET_TYPE_DEBT?6?: 'TRUSTMF Money Market Fund'!$B$6:$B$40
Name XDO_?ASSET_TYPE_DEBT?6?: 'TRUSTMF Overnight Fund'!$B$6:$B$11
Name XDO_?ASSET_TYPE_DEBT?6?: 'TRUSTMF Short Duration Fund'!$B$6:$B$20
Name XDO_?ASSET_TYPE_MM?: 'TRUSTMF Banking & PSU Fund'!$B$9:$B$38
Name XDO_?ASSET_TYPE_MM?1?: 'TRUSTMF Liquid Fund'!$B$8:$B$14
Name XDO_?ASSET_TYPE_MM?2?: 'TRUSTMF Money Market Fund'!$B$8:$B$24
Name XDO_?ASSET_TYPE_MM?2?: 'TRUSTMF Overnight Fund'!$B$8:$B$15
Name XDO_?ASSET_TYPE_MM?2?: 'TRUSTMF Short Duration Fund'!$B$8:$B$34
Name XDO_?AUM?: 'TRUSTMF Banking & PSU Fund'!#REF!
Name XDO_?AUM?1?: 'TRUSTMF Liquid Fund'!#REF!
Name XDO_?AUM?1?: 'TRUSTMF Liquid Fund'!#REF!
Name XDO_?AUM?2?: 'TRUSTMF Short Duration Fund'!#REF!
Name XDO_?AUM?2?: 'TRUSTMF Money Market Fund'!#REF!
Name XDO_?AUM?2?: 'TRUSTMF Overnight Fund'!#REF!
Name XDO_?AUM?2?: 'TRUSTMF Short Duration Fund'!#REF!
Name XDO_?CORPORATE_DIV_RATE?: 'TRUSTMF Banking & PSU Fund'!$G$29:$G$81
Name XDO_?CORPORATE_DIV_RATE?1?: 'TRUSTMF Liquid Fund'!$G$19:$G$95
Name XDO_?CORPORATE_DIV_RATE?2?: 'TRUSTMF Money Market Fund'!$G$9:$G$68
Name XDO_?CORPORATE_DIV_RATE?2?: 'TRUSTMF Overnight Fund'!$G$8:$G$47
Name XDO_?CORPORATE_DIV_RATE?2?: 'TRUSTMF Short Duration Fund'!$G$21:$G$68
Name XDO_?CS_MARKET_VALUE_DEBT_NIL?: 'TRUSTMF Banking & PSU Fund'!#REF!
Name XDO_?CS_MARKET_VALUE_DEBT_NIL?: 'TRUSTMF Banking & PSU Fund'!#REF!
Name XDO_?CS_MARKET_VALUE_DEBT_NIL?: 'TRUSTMF Banking & PSU Fund'!#REF!
Name XDO_?CS_MARKET_VALUE_DEBT_NIL?: 'TRUSTMF Banking & PSU Fund'!#REF!
Name XDO_?CS_MARKET_VALUE_DRV_NIL?: 'TRUSTMF Banking & PSU Fund'!#REF!
Name XDO_?CS_MARKET_VALUE_DRV_NIL?: 'TRUSTMF Banking & PSU Fund'!#REF!
Name XDO_?CS_MARKET_VALUE_DRV_NIL?: 'TRUSTMF Banking & PSU Fund'!#REF!
Name XDO_?CS_MARKET_VALUE_DRV_NIL?: 'TRUSTMF Banking & PSU Fund'!#REF!
Name XDO_?CS_MARKET_VALUE_DRV_NIL?1?: 'TRUSTMF Liquid Fund'!#REF!
Name XDO_?CS_MARKET_VALUE_DRV_NIL?1?: 'TRUSTMF Liquid Fund'!#REF!
Name XDO_?CS_MARKET_VALUE_DRV_NIL?1?: 'TRUSTMF Liquid Fund'!#REF!
Name XDO_?CS_MARKET_VALUE_DRV_NIL?1?: 'TRUSTMF Liquid Fund'!#REF!
Name XDO_?CS_MARKET_VALUE_DRV_NIL?2?: 'TRUSTMF Short Duration Fund'!#REF!
Name XDO_?CS_MARKET_VALUE_DRV_NIL?2?: 'TRUSTMF Money Market Fund'!#REF!
Name XDO_?CS_MARKET_VALUE_DRV_NIL?2?: 'TRUSTMF Overnight Fund'!#REF!
Name XDO_?CS_MARKET_VALUE_DRV_NIL?2?: 'TRUSTMF Short Duration Fund'!#REF!
Name XDO_?CS_MARKET_VALUE_EQU_NIL?: 'TRUSTMF Banking & PSU Fund'!#REF!
Name XDO_?CS_MARKET_VALUE_EQU_NIL?: 'TRUSTMF Banking & PSU Fund'!#REF!
Name XDO_?CS_MARKET_VALUE_EQU_NIL?: 'TRUSTMF Banking & PSU Fund'!#REF!
Name XDO_?CS_MARKET_VALUE_EQU_NIL?: 'TRUSTMF Banking & PSU Fund'!#REF!
Name XDO_?CS_MARKET_VALUE_MM_NIL?: 'TRUSTMF Banking & PSU Fund'!$E$13
Name XDO_?CS_PER_NET_ASST_DEBT_NIL?: 'TRUSTMF Banking & PSU Fund'!#REF!
Name XDO_?CS_PER_NET_ASST_DEBT_NIL?: 'TRUSTMF Banking & PSU Fund'!#REF!
Name XDO_?CS_PER_NET_ASST_DEBT_NIL?: 'TRUSTMF Banking & PSU Fund'!#REF!
Name XDO_?CS_PER_NET_ASST_DEBT_NIL?: 'TRUSTMF Banking & PSU Fund'!#REF!
Name XDO_?CS_PER_NET_ASST_DRV_NIL?: 'TRUSTMF Banking & PSU Fund'!#REF!
Name XDO_?CS_PER_NET_ASST_DRV_NIL?: 'TRUSTMF Banking & PSU Fund'!#REF!
Name XDO_?CS_PER_NET_ASST_DRV_NIL?: 'TRUSTMF Banking & PSU Fund'!#REF!
Name XDO_?CS_PER_NET_ASST_DRV_NIL?: 'TRUSTMF Banking & PSU Fund'!#REF!
Name XDO_?CS_PER_NET_ASST_DRV_NIL?1?: 'TRUSTMF Liquid Fund'!#REF!

Sheet TRUSTMF Banking & PSU Fund
A1: MONTHLY PORTFOLIO STATEMENT AS ON February 28, 2026
A2: [Pursuant to Regulation 59 A of Securities and Exchange Board of India (Mutual Funds)
A4: TRUSTMF Banking & PSU Fund (An open ended debt scheme predominantly investing in debt instruments of banks, Public Sector Undertakings,Public Financial Institutions and Municipal Bonds)
A5: Name of Instrument | B5: ISIN | C5: Rating | D5: Quantity | E5: Market Value (In Rs. lakh) | F5: % To Net Assets | G5: Yield to Maturity (YTM) | H5: Yield to Call (YTC) ^^
A6: Debt Instruments
A7: (a) Listed / awaiting listing on Stock Exchange
A8: Govt Securities / SDL
A9: 6.75% GOI 23-DEC-2029 | B9: IN0020240183 | C9: SOVEREIGN | D9: 1500000 | E9: 1528.8435 | F9: 0.11695979 | G9: 0.0618435
A10: 7.04% GOI - 03-JUN-2029 | B10: IN0020240050 | C10: SOVEREIGN | D10: 500000 | E10: 513.9325 | F10: 0.039316933 | G10: 0.0610105
A11: Subtotal | E11: 2042.776 | F11: 0.15627672
A12: Non Convertible Debentures
A13: 7.77% REC Limited 31-MAR-2028 ** | B13: INE020B08EH0 | C13: CRISIL AAA | D13: 1400000 | E13: 1419.103 | F13: 0.10856441 | G13: 0.070483
A14: 7.48% National Bank for Agriculture and Rural Development 15-SEP-2028 | B14: INE261F08EO7 | C14: CRISIL AAA | D14: 1400000 | E14: 1408.8746 | F14: 0.10778191 | G14: 0.071796
A15: 7.59% National Housing Bank 14-JUL-2027 | B15: INE557F08FY4 | C15: CRISIL AAA | D15: 1300000 | E15: 1309.3275 | F15: 0.10016635 | G15: 0.070274
A16: 7.35% Export Import Bank of India 27-JUL-2028 ** | B16: INE514E08GE8 | C16: CRISIL AAA | D16: 1150000 | E16: 1158.7388 | F16: 0.088645996 | G16: 0.070283
A17: 6.47% Indian Railway Finance Corporation Limited 30-MAY-2028 ** | B17: INE053F08510 | C17: CRISIL AAA | D17: 900000 | E17: 888.3603 | F17: 0.067961459 | G17: 0.07091
A18: 7.60% Power Finance Corporation Limited 13-APR-2029 ** | B18: INE134E08MX3 | C18: CRISIL AAA | D18: 800000 | E18: 809.0088 | F18: 0.0618909 | G18: 0.071967
A19: 7.70% HDFC Bank Limited 16-MAY-2028 ** | B19: INE040A08955 | C19: CRISIL AAA | D19: 800000 | E19: 806.9288 | F19: 0.061731776 | G19: 0.072481
A20: 7.68% Small Industries Development Bank of India 09-JUL-2027 ** | B20: INE556F08KO7 | C20: CRISIL AAA | D20: 500000 | E20: 503.148 | F20: 0.038491896 | G20: 0.0724
A21: 7.13% Power Finance Corporation Limited 15-JUL-2026 | B21: INE134E08LP1 | C21: CRISIL AAA | D21: 500000 | E21: 498.9945 | F21: 0.038174144 | G21: 0.073609
A22: 6.14% Indian Oil Corporation Limited 18-FEB-2027 ** | B22: INE242A08502 | C22: CRISIL AAA | D22: 500000 | E22: 495.7785 | F22: 0.037928114 | G22: 0.06995
A23: 7.9265% LIC Housing Finance Limited 14-JUL-2027 ** | B23: INE115A07QS3 | C23: CRISIL AAA | D23: 300000 | E23: 302.5503 | F23: 0.023145744 | G23: 0.07235
A24: 7.68% Small Industries Development Bank of India 10-SEP-2027 ** | B24: INE556F08KQ2 | C24: CRISIL AAA | D24: 300000 | E24: 301.8618 | F24: 0.023093072 | G24: 0.0724
... A26: 9.64% Power Grid Corporation of India Limited 31-MAY-2026 ** | B26: INE752E07IL7 | C26: ICRA AAA | D26: 50000 | E26: 50.2894 | F26: 0.0038472465 | G26: 0.07345
A27: Subtotal | E27: 10053.246 | F27: 0.76909476
A28: (b) Privately placed / Unlisted
A29: Subtotal | E29: NIL | F29: NIL
A30: (c) Securitised Debt
A31: Subtotal | E31: NIL | F31: NIL
A32: Total | E32: 12096.022 | F32: 0.92537149
A34: Money Market Instruments
A35: Tri Party Repo (TREPs)
A36: TREPS | E36: 387.95487 | F36: 0.029679376
A37: Subtotal | E37: 387.95487 | F37: 0.029679376
A38: Total | E38: 387.95487 | F38: 0.029679376
A40: Others
A41: Investment in Corporate Debt Market Development Fund (CDMDF)$$ | B41: INF0RQ622028 | D41: 940.253 | E41: 109.05906 | F41: 0.0083432512
A42: Total | E42: 109.05906 | F42: 0.0083432512
A44: Net Current Assets | E44: 478.49499 | F44: 0.036605888
A45: GRAND TOTAL | E45: 13071.531 | F45: 1
...

Sheet TRUSTMF Liquid Fund
A1: MONTHLY PORTFOLIO STATEMENT AS ON February 28, 2026
A2: [Pursuant to Regulation 59 A of Securities and Exchange Board of India (Mutual Funds)
A4: TRUSTMF LIQUID Fund (An Open Ended Liquid Scheme)
A5: Name of Instrument | B5: ISIN | C5: Rating | D5: Quantity | E5: Market Value (In Rs. lakh) | F5: % To Net Assets | G5: Yield to Maturity (YTM) | H5: Yield to Call (YTC) ^^
A6: Debt Instruments
A7: (a) Listed / awaiting listing on Stock Exchange
A8: Subtotal | E8: NIL | F8: NIL
A9: (b) Privately placed / Unlisted
A10: Subtotal | E10: =E8 -> NIL | F10: =F8 -> NIL
A11: (c) Securitised Debt
A12: Subtotal | E12: NIL | F12: NIL
A13: Total | E13: NIL | F13: NIL
A15: Money Market Instruments
A16: Certificate of Deposits
A17: Axis Bank Limited 05-MAR-2026 # | B17: INE238AD6AO8 | C17: CRISIL A1+ | D17: 5000000 | E17: 4997.04 | F17: 0.053013091 | G17: 0.054007
A18: Bank of Baroda 17-MAR-2026 # ** | B18: INE028A16KU8 | C18: CARE A1+ | D18: 5000000 | E18: 4987.865 | F18: 0.052915754 | G18: 0.055503
A19: Axis Bank Limited 15-MAY-2026 # | B19: INE238AD6BA5 | C19: CRISIL A1+ | D19: 5000000 | E19: 4927.005 | F19: 0.052270097 | G19: 0.0721
A20: Canara Bank 06-MAR-2026 # ** | B20: INE476A16A99 | C20: CRISIL A1+ | D20: 2500000 | E20: 2498.1175 | F20: 0.026502275 | G20: 0.054997
A21: Canara Bank 13-MAR-2026 # | B21: INE476A16B31 | C21: CRISIL A1+ | D21: 2500000 | E21: 2495.4475 | F21: 0.02647395 | G21: 0.055494
A22: Small Industries Development Bank of India 17-MAR-2026 # ** | B22: INE556F16BE0 | C22: CARE A1+ | D22: 2500000 | E22: 2493.8475 | F22: 0.026456975 | G22: 0.056299
A23: Canara Bank 18-MAR-2026 # | B23: INE476A16B64 | C23: CRISIL A1+ | D23: 2500000 | E23: 2493.5675 | F23: 0.026454005 | G23: 0.055382
A24: HDFC Bank Limited 18-MAR-2026 # ** | B24: INE040A16IC5 | C24: CARE A1+ | D24: 2500000 | E24: 2493.5575 | F24: 0.026453899 | G24: 0.0554915
A25: Punjab National Bank 18-MAR-2026 # | B25: INE160A16RK5 | C25: CARE A1+ | D25: 2500000 | E25: 2493.5375 | F25: 0.026453687 | G25: 0.055648
A26: National Bank for Agriculture and Rural Development 24-MAR-2026 # ** | B26: INE261F16991 | C26: CRISIL A1+ | D26: 2500000 | E26: 2491.145 | F26: 0.026428305 | G26: 0.056411
A27: Canara Bank 11-MAY-2026 # ** | B27: INE476A16E46 | C27: CRISIL A1+ | D27: 2500000 | E27: 2465.5175 | F27: 0.026156425 | G27: 0.0719
A28: Punjab National Bank 18-MAY-2026 # ** | B28: INE160A16UK9 | C28: CARE A1+ | D28: 2500000 | E28: 2462.8425 | F28: 0.026128047 | G28: 0.0706015
... A30: Bank of Baroda 25-MAY-2026 # ** | B30: INE028A16JR6 | C30: IND A1+ | D30: 2500000 | E30: 2459.7025 | F30: 0.026094735 | G30: 0.070351
A31: Subtotal | E31: 42220.087 | F31: 0.44790863
A32: Commercial Papers
A33: ICICI Securities Limited 02-MAR-2026 | B33: INE763G14C61 | C33: CRISIL A1+ | D33: 5000000 | E33: 4999.295 | F33: 0.053037014 | G33: 0.051487
A34: Small Industries Development Bank of India 20-MAR-2026 | B34: INE556F14LX4 | C34: CARE A1+ | D34: 5000000 | E34: 4985.34 | F34: 0.052888967 | G34: 0.056497
A35: Reliance Jio Infocomm Limited 23-MAR-2026 ** | B35: INE110L14UM2 | C35: CRISIL A1+ | D35: 5000000 | E35: 4982.06 | F35: 0.05285417 | G35: 0.0597515
A36: National Bank for Agriculture and Rural Development 14-MAY-2026 ** | B36: INE261F14OS5 | C36: ICRA A1+ | D36: 5000000 | E36: 4927.08 | F36: 0.052270892 | G36: 0.073
A37: Bajaj Financial Securities Limited 10-MAR-2026 ** | B37: INE01C314DN2 | C37: CRISIL A1+ | D37: 2500000 | E37: 2496.2375 | F37: 0.026482331 | G37: 0.0611475
A38: Kotak Securities Ltd. 24-MAR-2026 ** | B38: INE028E14UF5 | C38: ICRA A1+ | D38: 2500000 | E38: 2490.225 | F38: 0.026418545 | G38: 0.0623
A39: Export Import Bank of India 27-MAY-2026 ** | B39: INE514E14TF6 | C39: CRISIL A1+ | D39: 2500000 | E39: 2458.685 | F39: 0.02608394 | G39: 0.0704995
A40: NTPC Limited 10-MAR-2026 ** | B40: INE733E14BU9 | C40: CRISIL A1+ | D40: 1300000 | E40: 1298.2203 | F40: 0.013772688 | G40: 0.0555935
A41: Subtotal | E41: 28637.143 | F41: 0.30380855
A42: Treasury Bills
A43: 91 Days Treasury Bill 14-MAY-2026 | B43: IN002025X455 | C43: SOVEREIGN | D43: 8000000 | E43: 7915.912 | F43: 0.083979108 | G43: 0.0524
...

Sheet TRUSTMF Short Duration Fund
A1: ='TRUSTMF Banking & PSU Fund'!A1:H1 -> MONTHLY PORTFOLIO STATEMENT AS ON February 28, 2026
A2: [Pursuant to Regulation 59 A of Securities and Exchange Board of India (Mutual Funds)
A4: TRUSTMF SHORT DURATION FUND (An open ended short term debt scheme investing in instruments such that the Macaulay duration of the portfolio is between 1 to 3 years)
A5: Name of Instrument | B5: ISIN | C5: Rating | D5: Quantity | E5: Market Value (In Rs. lakh) | F5: % To Net Assets | G5: Yield to Maturity (YTM) | H5: Yield to Call (YTC) ^^
A6: Debt Instruments
A7: (a) Listed / awaiting listing on Stock Exchange
A8: Govt Securities / SDL
A9: 7.32% GOI 13-NOV-2030 | B9: IN0020230135 | C9: SOVEREIGN | D9: 500000 | E9: 520.2985 | F9: 0.056833129 | G9: 0.063051
A10: Subtotal | E10: 520.2985 | F10: 0.056833129
A11: Non Convertible Debentures
A12: 7.35% Export Import Bank of India 27-JUL-2028 | B12: INE514E08GE8 | C12: CRISIL AAA | D12: 1150000 | E12: 1160.9836 | F12: 0.12681631 | G12: 0.069207
A13: 7.77% REC Limited 31-MAR-2028 ** | B13: INE020B08EH0 | C13: CRISIL AAA | D13: 1100000 | E13: 1116.7255 | F13: 0.12198191 | G13: 0.0695
A14: 7.74% LIC Housing Finance Limited 11-FEB-2028 | B14: INE115A07QW5 | C14: CRISIL AAA | D14: 1000000 | E14: 1009.476 | F14: 0.11026686 | G14: 0.07195
A15: 7.7951% Bajaj Finance Limited 10-DEC-2027 ** | B15: INE296A07TF2 | C15: CRISIL AAA | D15: 1000000 | E15: 1007.678 | F15: 0.11007046 | G15: 0.0729
A16: 7.01% National Bank for Agriculture and Rural Development 16-MAR-2029 ** | B16: INE261F08ES8 | C16: CRISIL AAA | D16: 1000000 | E16: 997.965 | F16: 0.10900949 | G16: 0.0709
A17: 7.20% Power Grid Corporation of India Limited 09-AUG-2027 ** | B17: INE752E07OG5 | C17: CRISIL AAA | D17: 900000 | E17: 903.96 | F17: 0.098741156 | G17: 0.06825
A18: 6.47% Indian Railway Finance Corporation Limited 30-MAY-2028 ** | B18: INE053F08510 | C18: CRISIL AAA | D18: 900000 | E18: 891.2952 | F18: 0.097357758 | G18: 0.069513
A19: Subtotal | E19: 7088.0834 | F19: 0.77424393
A20: (b) Privately placed / Unlisted
A21: Subtotal | E21: NIL | F21: NIL
A22: (c) Securitised Debt
A23: Subtotal | E23: NIL | F23: NIL
A24: Total | E24: =E10+E19 -> 7608.3819 | F24: =F10+F19 -> 0.83107706
A26: Money Market Instruments
A27: Treasury Bills
A28: 182 Days Treasury Bill 05-MAR-2026 | B28: IN002025Y230 | C28: SOVEREIGN | D28: 30000 | E28: 29.98356 | F28: 0.0032751575 | G28: 0.05
A29: Subtotal | E29: 29.98356 | F29: 0.0032751575
A30: Tri Party Repo (TREPs)
A31: TREPS | E31: 1244.773 | F31: 0.13596877
A32: Subtotal | E32: 1244.773 | F32: 0.13596877
A33: Total | E33: 1274.7566 | F33: 0.13924392
A35: Others
A36: Investment in Corporate Debt Market Development Fund (CDMDF)$$ | B36: INF0RQ622028 | D36: 319.544 | E36: 37.276939 | F36: 0.0040718263
A37: Total | E37: =E36 -> 37.276939 | F37: =F36 -> 0.0040718263
A39: Net Current Assets | E39: 234.42983 | F39: 0.025607187
A40: GRAND TOTAL | E40: 9154.8452 | F40: 1
A42: ** Non Traded Securities
A43: # Unlisted Securities
A44: ^^ As per AMFI Best Practices Circular dated 24 March 2021, Yield to Call (YTC) to be disclosed for Perpetual Bonds issued by Banks.
A45: $$ Investment by Mutual Fund Schemes in units of Corporate Debt Market Development Fund as mandated by SEBI vide it's circular SEBI/HO/IMD/PoD2/P/CIR/2023/129 dated July 27, 2023. Further, Average Maturity, YTM and Duration has been calculated in line with note 5.5 of the captioned circular.
...

Sheet TRUSTMF Overnight Fund
A1: ='TRUSTMF Banking & PSU Fund'!A1:H1 -> MONTHLY PORTFOLIO STATEMENT AS ON February 28, 2026
A2: [Pursuant to Regulation 59 A of Securities and Exchange Board of India (Mutual Funds)
A4: TRUSTMF OVERNIGHT FUND (An open ended debt scheme investing in overnight securities)
A5: Name of Instrument | B5: ISIN | C5: Rating | D5: Quantity | E5: Market Value (In Rs. lakh) | F5: % To Net Assets | G5: Yield to Maturity (YTM) | H5: Yield to Call (YTC) ^^
A6: Debt Instruments
A7: (a) Listed / awaiting listing on Stock Exchange
A8: Subtotal | E8: NIL | F8: NIL
A9: (b) Privately placed / Unlisted
A10: Subtotal | E10: NIL | F10: NIL
A11: (c) Securitised Debt
A12: Subtotal | E12: NIL | F12: NIL
A13: Total | E13: NIL | F13: NIL
A15: Money Market Instruments
A16: Treasury Bills
A17: 182 Days Treasury Bill 05-MAR-2026 | B17: IN002025Y230 | C17: SOVEREIGN | D17: 226000 | E17: 225.87615 | F17: 0.02468519 | G17: 0.05
A18: Subtotal | E18: 225.87615 | F18: 0.02468519
A19: Tri Party Repo (TREPs)
A20: TREPS | E20: 8809.3181 | F20: 0.96273861
A21: Subtotal | E21: 8809.3181 | F21: 0.96273861
A22: Total | E22: 9035.1943 | F22: 0.9874238
A24: Others
A25: Total | E25: NIL | F25: NIL
A27: Net Current Assets | E27: 115.07561 | F27: 0.012576199
A28: GRAND TOTAL | E28: 9150.2699 | F28: 1
A30: ** Non Traded Securities
A31: # Unlisted Securities
A32: ^^ As per AMFI Best Practices Circular dated 24 March 2021, Yield to Call (YTC) to be disclosed for Perpetual Bonds issued by Banks.
A35: Notes :
A36: 1) The provision made for investment in security below investment grade as on February 28, 2026 is Rs Nil and its percentage to Net Asset Value is Nil.
A37: 2) Net Assets Value per unit (in Rs) are as follows :
A38: Plan/Option | E38: As on February 28, 2026 | G38: As on January 31, 2026
A39: Direct Plan - Daily IDCW | E39: 1241.4695 | G39: 1237.9796
A40: Direct Plan - Growth Option | E40: 1268.4117 | G40: 1263.8778
A41: Regular Plan - Daily IDCW | E41: 1239.9995 | G41: 1237.271
A42: Regular Plan - Growth Option | E42: 1265.8227 | G42: 1261.3471
A44: 3) Details of Dividend declared per unit (in Rs.) during the Month of February 2026
A45: Plan/Option | E45: Individuals/HUF | G45: Other than Individual/HUF
A46: Direct Plan - Daily IDCW | E46: 0.64 | G46: 0.64
A47: Regular Plan - Daily IDCW | E47: 2.24 | G47: 2.24
A48: 4) No Bonus declared during the month February 2026
...

Sheet TRUSTMF Money Market Fund
A1: ='TRUSTMF Banking & PSU Fund'!A1:H1 -> MONTHLY PORTFOLIO STATEMENT AS ON February 28, 2026
A2: [Pursuant to Regulation 59 A of Securities and Exchange Board of India (Mutual Funds)
A4: TRUSTMF MONEY MARKET FUND (An open ended debt scheme investing in money market instruments)
A5: Name of Instrument | B5: ISIN | C5: Rating | D5: Quantity | E5: Market Value (In Rs. lakh) | F5: % To Net Assets | G5: Yield to Maturity (YTM) | H5: Yield to Call (YTC) ^^
A6: Debt Instruments
A7: (a) Listed / awaiting listing on Stock Exchange
A8: Subtotal | E8: NIL | F8: NIL
A9: (b) Privately placed / Unlisted
A10: Subtotal | E10: NIL | F10: NIL
A11: (c) Securitised Debt
A12: Subtotal | E12: NIL | F12: NIL
A13: Total | E13: NIL | F13: NIL
A15: Money Market Instruments
A16: Certificate of Deposits
A17: Axis Bank Limited 12-JUN-2026 # | B17: INE238AD6AU5 | C17: CRISIL A1+ | D17: 1200000 | E17: 1176.5916 | F17: 0.089110492 | G17: 0.070501
A18: Canara Bank 03-JUN-2026 # ** | B18: INE476A16F60 | C18: CRISIL A1+ | D18: 1000000 | E18: 982.242 | F18: 0.074391205 | G18: 0.0702005
A19: Punjab National Bank 12-JUN-2026 # ** | B19: INE160A16UA0 | C19: ICRA A1+ | D19: 1000000 | E19: 980.521 | F19: 0.074260864 | G19: 0.0704005
A20: HDFC Bank Limited 11-SEP-2026 # ** | B20: INE040A16HN4 | C20: CARE A1+ | D20: 1000000 | E20: 963.932 | F20: 0.073004477 | G20: 0.0704
A21: Small Industries Development Bank of India 14-JAN-2027 # ** | B21: INE556F16BV4 | C21: CARE A1+ | D21: 1000000 | E21: 942.194 | F21: 0.071358125 | G21: 0.0702
A22: Kotak Mahindra Bank Limited 04-FEB-2027 # ** | B22: INE237AD6133 | C22: CRISIL A1+ | D22: 1000000 | E22: 939.938 | F22: 0.071187264 | G22: 0.0685995
A23: National Bank for Agriculture and Rural Development 17-FEB-2027 # ** | B23: INE261F16AK6 | C23: CRISIL A1+ | D23: 1000000 | E23: 936.806 | F23: 0.070950059 | G23: 0.06975
A24: Axis Bank Limited 04-MAR-2026 # ** | B24: INE238AD6AN0 | C24: CRISIL A1+ | D24: 150000 | E24: 149.9334 | F24: 0.011355375 | G24: 0.0540035
A25: Bank of Baroda 03-JUN-2026 # ** | B25: INE028A16KG7 | C25: CARE A1+ | D25: 100000 | E25: 98.2217 | F25: 0.0074389312 | G25: 0.0703005
A26: Subtotal | E26: 7170.3797 | F26: 0.54305679
A27: Commercial Papers
A28: NTPC Limited 10-MAR-2026 ** | B28: INE733E14BU9 | C28: CRISIL A1+ | D28: 1200000 | E28: 1198.3572 | F28: 0.090758934 | G28: 0.0555935
A29: REC Limited 10-JUN-2026 ** | B29: INE020B14698 | C29: ICRA A1+ | D29: 1000000 | E29: 980.998 | F29: 0.07429699 | G29: 0.0699995
A30: L&T Finance Limited 21-MAY-2026 ** | B30: INE498L14DY2 | C30: CRISIL A1+ | D30: 500000 | E30: 491.8895 | F30: 0.037253806 | G30: 0.0743
A31: Subtotal | E31: 2671.2447 | F31: 0.20230973
A32: Treasury Bills
A33: 364 Days Treasury Bill 23-OCT-2026 | B33: IN002025Z302 | C33: SOVEREIGN | D33: 500000 | E33: 483.079 | F33: 0.036586533 | G33: 0.054175
A34: 364 Days Treasury Bill 06-NOV-2026 | B34: IN002025Z328 | C34: SOVEREIGN | D34: 500000 | E34: 481.917 | F34: 0.036498527 | G34: 0.054785
A35: 364 Days Treasury Bill 25-FEB-2027 | B35: IN002025Z476 | C35: SOVEREIGN | D35: 500000 | E35: 474.064 | F35: 0.035903772 | G35: 0.055316
A36: 182 Days Treasury Bill 05-MAR-2026 | B36: IN002025Y230 | C36: SOVEREIGN | D36: 30000 | E36: 29.98356 | F36: 0.0022708387 | G36: 0.05
A37: Subtotal | E37: 1469.0436 | F37: 0.11125967
A38: Tri Party Repo (TREPs)
A39: TREPS | E39: 1814.8765 | F39: 0.13745172
A40: Subtotal | E40: 1814.8765 | F40: 0.13745172
A41: Total | E41: 13125.544 | F41: 0.99407791
A43: Others
...

Sheet TRUSTMF Corporate Bond Fund
A1: ='TRUSTMF Banking & PSU Fund'!A1:H1 -> MONTHLY PORTFOLIO STATEMENT AS ON February 28, 2026
A2: [Pursuant to Regulation 59 A of Securities and Exchange Board of India (Mutual Funds)
A4: TRUSTMF CORPORATE BOND FUND (An open ended debt scheme predominantly investing in AA+ and above rated corporate bonds)
A5: Name of Instrument | B5: ISIN | C5: Rating | D5: Quantity | E5: Market Value (In Rs. lakh) | F5: % To Net Assets | G5: Yield to Maturity (YTM) | H5: Yield to Call (YTC) ^^
A6: Debt Instruments
A7: (a) Listed / awaiting listing on Stock Exchange
A8: Govt Securities / SDL
A9: 6.75% GOI 23-DEC-2029 | B9: IN0020240183 | C9: SOVEREIGN | D9: 1000000 | E9: 1022.665 | F9: 0.081982661 | G9: 0.060714
A10: 7.04% GOI 03-JUN-2029 | B10: IN0020240050 | C10: SOVEREIGN | D10: 500000 | E10: 515.474 | F10: 0.041323337 | G10: 0.059754
A11: Subtotal | E11: 1538.139 | F11: 0.123306
A12: Non Convertible Debentures
A13: 7.48% National Bank for Agriculture and Rural Development 15-SEP-2028 | B13: INE261F08EO7 | C13: CRISIL AAA | D13: 1500000 | E13: 1513.26 | F13: 0.12131156 | G13: 0.0706
A14: 7.77% REC Limited 31-MAR-2028 ** | B14: INE020B08EH0 | C14: CRISIL AAA | D14: 1400000 | E14: 1421.287 | F14: 0.11393848 | G14: 0.0695
A15: 7.35% Export Import Bank of India 27-JUL-2028 | B15: INE514E08GE8 | C15: CRISIL AAA | D15: 1350000 | E15: 1362.8938 | F15: 0.10925735 | G15: 0.069207
A16: 6.47% Indian Railway Finance Corporation Limited 30-MAY-2028 ** | B16: INE053F08510 | C16: CRISIL AAA | D16: 1100000 | E16: 1089.3608 | F16: 0.087329377 | G16: 0.069513
A17: 7.60% Power Finance Corporation Limited 13-APR-2029 | B17: INE134E08MX3 | C17: CRISIL AAA | D17: 1000000 | E17: 1014.259 | F17: 0.081308788 | G17: 0.070817
A18: 7.70% HDFC Bank Limited 16-MAY-2028 ** | B18: INE040A08955 | C18: CRISIL AAA | D18: 1000000 | E18: 1011.24 | F18: 0.081066768 | G18: 0.0711
A19: 7.9265% LIC Housing Finance Limited 14-JUL-2027 ** | B19: INE115A07QS3 | C19: CRISIL AAA | D19: 500000 | E19: 504.742 | F19: 0.040462999 | G19: 0.07125
A20: 7.68% Small Industries Development Bank of India 10-SEP-2027 ** | B20: INE556F08KQ2 | C20: CRISIL AAA | D20: 500000 | E20: 504.3055 | F20: 0.040428006 | G20: 0.070534
A21: 7.68% Small Industries Development Bank of India 09-JUL-2027 ** | B21: INE556F08KO7 | C21: CRISIL AAA | D21: 500000 | E21: 504.151 | F21: 0.040415621 | G21: 0.070534
A22: 7.20% Power Grid Corporation of India Limited 09-AUG-2027 ** | B22: INE752E07OG5 | C22: CRISIL AAA | D22: 100000 | E22: 100.44 | F22: 0.0080518435 | G22: 0.06825
A23: 6.59% Summit Digitel Infrastructure Private Limited 16-JUN-2026 ** | B23: INE507T07062 | C23: CRISIL AAA | D23: 70000 | E23: 69.86252 | F23: 0.0056005782 | G23: 0.074699
A24: 9.64% Power Grid Corporation of India Limited 31-MAY-2026 ** | B24: INE752E07IL7 | C24: ICRA AAA | D24: 50000 | E24: 50.2251 | F24: 0.0040263306 | G24: 0.07275
A25: Subtotal | E25: 9146.0268 | F25: 0.73319769
A26: (b) Privately placed / Unlisted
A27: Subtotal | E27: NIL | F27: NIL
A28: (c) Securitised Debt
A29: Subtotal | E29: NIL | F29: NIL
A30: Total | E30: =E11+E25 -> 10684.166 | F30: =F11+F25 -> 0.85650369
A32: Money Market Instruments
A33: Treasury Bills
A34: 182 Days Treasury Bill 05-MAR-2026 | B34: IN002025Y230 | C34: SOVEREIGN | D34: 60000 | E34: 59.96712 | F34: 0.0048073065 | G34: 0.05
A35: Subtotal | E35: 59.96712 | F35: 0.0048073065
A36: Tri Party Repo (TREPs)
A37: TREPS | E37: 1212.7873 | F37: 0.097223949
A38: Subtotal | E38: 1212.7873 | F38: 0.097223949
A39: Total | E39: 1272.7544 | F39: 0.10203125
A41: Others
A42: Investment in Corporate Debt Market Development Fund (CDMDF)$$ | B42: INF0RQ622028 | D42: 1253.735 | E42: 146.25655 | F42: 0.01172476
A43: Total | E43: =E42 -> 146.25655 | F43: =F42 -> 0.01172476
...

Sheet TRUSTMF FMP - Series II
A1: ='TRUSTMF Banking & PSU Fund'!A1:H1 -> MONTHLY PORTFOLIO STATEMENT AS ON February 28, 2026
A2: [Pursuant to Regulation 59 A of Securities and Exchange Board of India (Mutual Funds)
A4: TRUSTMF Fixed Maturity Plan - Series II (1196 Days) (A close ended income scheme with relatively high interest rate risk and relatively high credit risk)
A5: Name of Instrument | B5: ISIN | C5: Rating | D5: Quantity | E5: Market Value (In Rs. lakh) | F5: % To Net Assets | G5: Yield to Maturity (YTM) | H5: Yield to Call (YTC) ^^
A6: Debt Instruments
A7: (a) Listed / awaiting listing on Stock Exchange
A8: Non Convertible Debentures
A9: 8.70% The Great Eastern Shipping Co. Ltd. 06-MAY-2026 ** | B9: INE017A08235 | C9: CARE AAA | D9: 500000 | E9: 500.383 | F9: 0.078072223 | G9: 0.077203
A10: 8.37% ONGC Petro Additions Ltd 16-JUN-2026 ** | B10: INE163N08263 | C10: ICRA AA+ | D10: 500000 | E10: 500.353 | F10: 0.078067542 | G10: 0.0767
A11: 7.56% REC Limited 30-JUN-2026 ** | B11: INE020B08ED9 | C11: CRISIL AAA | D11: 500000 | E11: 500.0665 | F11: 0.078022841 | G11: 0.071574
A12: 8.20% Tata Projects Ltd. 27-APR-2026 ** | B12: INE725H08121 | C12: IND AA | D12: 500000 | E12: 499.7895 | F12: 0.077979622 | G12: 0.079701
A13: 8.10% Aditya Birla Real Estate Limited 25-APR-2026 ** | B13: INE055A08037 | C13: CRISIL AA | D13: 500000 | E13: 499.5545 | F13: 0.077942956 | G13: 0.082
A14: 9.40% Avanse Financial Services Ltd. 08-JUL-2026 ** | B14: INE087P07345 | C14: CARE AA- | D14: 500000 | E14: 498.653 | F14: 0.0778023 | G14: 0.09635
A15: 6.59% Summit Digitel Infrastructure Private Limited 16-JUN-2026 ** | B15: INE507T07062 | C15: CRISIL AAA | D15: 430000 | E15: 429.15548 | F15: 0.066958954 | G15: 0.074699
A16: 10.48% Profectus Capital Pvt Ltd 28-MAY-2026 ** | B16: INE389Z07047 | C16: CRISIL A | D16: 400000 | E16: 400.6648 | F16: 0.062513697 | G16: 0.098999
A17: 10.49% Renserv Global Pvt Ltd 25-MAY-2026 ** | B17: INE0AY207012 | C17: CARE A (CE) | D17: 400000 | E17: 400.482 | F17: 0.062485176 | G17: 0.1009
A18: 8.75% Shriram Finance Limited 15-JUN-2026 ** | B18: INE721A07RH9 | C18: CRISIL AA+ | D18: 200000 | E18: 200.6036 | F18: 0.031299163 | G18: 0.078329
A19: 9.64% Power Grid Corporation of India Limited 31-MAY-2026 ** | B19: INE752E07IL7 | C19: ICRA AAA | D19: 137500 | E19: 138.11902 | F19: 0.021550011 | G19: 0.07275
A20: 8.02% Mindspace Business Parks REIT 13-APR-2026 ** | B20: INE0CCU07074 | C20: CRISIL AAA | D20: 130000 | E20: 130.11869 | F20: 0.02030176 | G20: 0.0742
... A22: 9.70% U.P. Power Corporation Ltd. 31-MAR-2026 ** | B22: INE540P07376 | C22: IND A+(CE) | D22: 200000 | E22: 100.1404 | F22: 0.015624399 | G22: 0.078555
A23: Subtotal | E23: 4923.282 | F23: 0.76815473
A24: (b) Privately placed / Unlisted
A25: Subtotal | E25: NIL | F25: NIL
A26: (c) Securitised Debt
A27: Subtotal | E27: NIL | F27: NIL
A28: Total | E28: 4923.282 | F28: 0.76815473
A30: Money Market Instruments
A31: Certificate of Deposits
A32: Bank of Baroda 03-JUN-2026 # ** | B32: INE028A16KG7 | C32: CARE A1+ | D32: 400000 | E32: 392.8868 | F32: 0.061300136 | G32: 0.0703005
A33: Axis Bank Limited 04-MAR-2026 # ** | B33: INE238AD6AN0 | C33: CRISIL A1+ | D33: 350000 | E33: 349.8446 | F33: 0.054584479 | G33: 0.0540035
A34: Axis Bank Limited 12-JUN-2026 # | B34: INE238AD6AU5 | C34: CRISIL A1+ | D34: 300000 | E34: 294.1479 | F34: 0.045894406 | G34: 0.070501
A35: Subtotal | E35: 1036.8793 | F35: 0.16177902
A36: Treasury Bills
A37: 182 Days Treasury Bill 05-MAR-2026 | B37: IN002025Y230 | C37: SOVEREIGN | D37: 4000 | E37: 3.997808 | F37: 0.00062375771 | G37: 0.05
A38: Subtotal | E38: 3.997808 | F38: 0.00062375771
A39: Tri Party Repo (TREPs)
A40: TREPS | E40: 204.47257 | F40: 0.031902818
A41: Subtotal | E41: 204.47257 | F41: 0.031902818
A42: Total | E42: 1245.3497 | F42: 0.1943056
A44: Others
...

Sheet TRUSTMF Flexi Cap Fund
A1: ='TRUSTMF FMP - Series II'!A1:H1 -> MONTHLY PORTFOLIO STATEMENT AS ON February 28, 2026
A2: [Pursuant to Regulation 59 A of Securities and Exchange Board of India (Mutual Funds)
A4: TRUSTMF FLEXI CAP FUND (An open ended dynamic equity scheme investing across large cap, mid cap, small cap stocks.)
A5: Name of Instrument | B5: ISIN | C5: Rating/Industry | D5: Quantity | E5: Market Value (In Rs. lakh) | F5: % To Net Assets | G5: Yield to Maturity (YTM) | H5: Yield to Call (YTC) ^^
A6: Equity & Equity related
A7: a) Listed / awaiting listing on Stock Exchanges
A8: ICICI Bank Limited | B8: INE090A01021 | C8: Banks | D8: 437373 | E8: 6030.9363 | F8: 0.054679152
A9: State Bank of India | B9: INE062A01020 | C9: Banks | D9: 457285 | E9: 5495.1938 | F9: 0.049821872
A10: HDFC Bank Limited | B10: INE040A01034 | C10: Banks | D10: 556071 | E10: 4936.5203 | F10: 0.044756689
A11: Reliance Industries Limited | B11: INE002A01018 | C11: Petroleum Products | D11: 334965 | E11: 4669.0771 | F11: 0.042331931
A12: Bharat Electronics Limited | B12: INE263A01024 | C12: Aerospace & Defense | D12: 839090 | E12: 3731.4332 | F12: 0.033830834
A13: Axis Bank Limited | B13: INE238A01034 | C13: Banks | D13: 250916 | E13: 3472.4265 | F13: 0.031482564
A14: Acutaas Chemicals Limited | B14: INE00FF01025 | C14: Pharmaceuticals & Biotechnology | D14: 159260 | E14: 3438.1049 | F14: 0.031171388
A15: Larsen & Toubro Limited | B15: INE018A01030 | C15: Construction | D15: 74534 | E15: 3188.7881 | F15: 0.028910972
A16: Bharti Airtel Limited | B16: INE397D01024 | C16: Telecom - Services | D16: 152468 | E16: 2865.3311 | F16: 0.025978367
A17: Titan Company Limited | B17: INE280A01028 | C17: Consumer Durables | D17: 59403 | E17: 2570.6648 | F17: 0.023306791
A18: Infosys Limited | B18: INE009A01021 | C18: IT - Software | D18: 196729 | E18: 2557.6737 | F18: 0.023189008
A19: TVS Motor Company Limited | B19: INE494B01023 | C19: Automobiles | D19: 65746 | E19: 2544.173 | F19: 0.023066604
... A43: One 97 Communications Limited | B43: INE982J01020 | C43: Financial Technology (Fintech) | D43: 109921 | E43: 1207.2623 | F43: 0.010945577
A44: Multi Commodity Exchange of India Limited | B44: INE745G01043 | C44: Capital Markets | D44: 49162 | E44: 1201.1751 | F44: 0.010890388 | I44: 1052685
A45: CG Power and Industrial Solutions Limited | B45: INE067A01029 | C45: Electrical Equipment | D45: 165593 | E45: 1200.8804 | F45: 0.010887716
A46: Eternal Limited | B46: INE758T01015 | C46: Retailing | D46: 486649 | E46: 1198.6165 | F46: 0.01086719
A47: Ather Energy Limited | B47: INE0LEZ01016 | C47: Automobiles | D47: 167033 | E47: 1187.4376 | F47: 0.010765838
A48: SBI Life Insurance Company Limited | B48: INE123W01016 | C48: Insurance | D48: 55232 | E48: 1125.1863 | F48: 0.01020144
A49: Apar Industries Limited | B49: INE372A01015 | C49: Electrical Equipment | D49: 10063 | E49: 1125.0937 | F49: 0.0102006
A50: HCL Technologies Limited | B50: INE860A01027 | C50: IT - Software | D50: 79820 | E50: 1108.7796 | F50: 0.010052689
A51: Neuland Laboratories Limited | B51: INE794A01010 | C51: Pharmaceuticals & Biotechnology | D51: 8079 | E51: 1036.1318 | F51: 0.0093940314
A52: Sansera Engineering Limited | B52: INE953O01021 | C52: Auto Components | D52: 40184 | E52: 941.18965 | F52: 0.0085332441
A53: Belrise Industries Limited | B53: INE894V01022 | C53: Auto Components | D53: 491003 | E53: 921.75993 | F53: 0.0083570856
A54: FSN E-Commerce Ventures Limited | B54: INE388Y01029 | C54: Retailing | D54: 324919 | E54: 862.59496 | F54: 0.0078206697
A55: Persistent Systems Limited | B55: INE262H01021 | C55: IT - Software | D55: 17969 | E55: 850.47277 | F55: 0.0077107645 | I55: 27478
A56: BSE Limited | B56: INE118H01025 | C56: Capital Markets | D56: 29541 | E56: 799.70441 | F56: 0.007250476
A57: Garuda Construction and Engineering Limited | B57: INE0JVO01026 | C57: Construction | D57: 394387 | E57: 700.51019 | F57: 0.006351137
A58: Vedanta Limited | B58: INE205A01025 | C58: Diversified Metals | D58: 86027 | E58: 618.01797 | F58: 0.0056032258
A59: Fractal Analytics Limited | B59: INE212S01015 | C59: IT - Software | D59: 77776 | E59: 605.48616 | F59: 0.0054896069
A60: Clean Max Enviro Energy Solutions Ltd | B60: INE647U01026 | C60: Power | D60: 56980 | E60: 599.9994 | F60: 0.0054398615
A61: Shaily Engineering Plastics Limited | B61: INE151G01028 | C61: Industrial Products | D61: 30734 | E61: 599.34373 | F61: 0.0054339169
A62: Welspun Living Limited | B62: INE192B01031 | C62: Textiles & Apparels | D62: 476699 | E62: 597.44686 | F62: 0.005416719
A63: K.P.R. Mill Limited | B63: INE930H01031 | C63: Textiles & Apparels | D63: 60390 | E63: 542.18142 | F63: 0.004915658
A64: Navin Fluorine International Limited | B64: INE048G01026 | C64: Chemicals & Petrochemicals | D64: 8595 | E64: 537.74617 | F64: 0.0048754461
...

Sheet TRUSTMF Small Cap Fund
A1: ='TRUSTMF Flexi Cap Fund'!A1:H1 -> MONTHLY PORTFOLIO STATEMENT AS ON February 28, 2026
A2: [Pursuant to Regulation 59 A of Securities and Exchange Board of India (Mutual Funds)
A4: TRUSTMF SMALL CAP FUND (An open-ended equity scheme predominantly investing in small cap stocks)
A5: Name of Instrument | B5: ISIN | C5: Rating/Industry | D5: Quantity | E5: Market Value (In Rs. lakh) | F5: % To Net Assets | G5: Yield to Maturity (YTM) | H5: Yield to Call (YTC) ^^
A6: Equity & Equity related
A7: a) Listed / awaiting listing on Stock Exchanges
A8: Karur Vysya Bank Limited | B8: INE036D01028 | C8: Banks | D8: 1656522 | E8: 5403.5748 | F8: 0.039019678
A9: Acutaas Chemicals Limited | B9: INE00FF01025 | C9: Pharmaceuticals & Biotechnology | D9: 203424 | E9: 4391.5173 | F9: 0.031711524
A10: City Union Bank Limited | B10: INE491A01021 | C10: Banks | D10: 1546930 | E10: 4378.5854 | F10: 0.031618141
A11: The Federal Bank Limited | B11: INE171A01029 | C11: Banks | D11: 1245946 | E11: 3735.9691 | F11: 0.026977754
A12: Navin Fluorine International Limited | B12: INE048G01026 | C12: Chemicals & Petrochemicals | D12: 57718 | E12: 3611.1267 | F12: 0.026076256
A13: Multi Commodity Exchange of India Limited | B13: INE745G01043 | C13: Capital Markets | D13: 130761 | E13: 3194.8835 | F13: 0.023070528
A14: TD Power Systems Limited | B14: INE419M01027 | C14: Electrical Equipment | D14: 346824 | E14: 3132.8612 | F14: 0.02262266
A15: S.J.S. Enterprises Limited | B15: INE284S01014 | C15: Auto Components | D15: 175235 | E15: 3083.6103 | F15: 0.022267015
A16: Laurus Labs Limited | B16: INE947Q01028 | C16: Pharmaceuticals & Biotechnology | D16: 274541 | E16: 2953.5121 | F16: 0.021327564
A17: Kirloskar Oil Engines Limited | B17: INE146L01010 | C17: Industrial Products | D17: 199653 | E17: 2781.5656 | F17: 0.020085924
A18: Lenskart Solutions Limited | B18: INE956O01016 | C18: Retailing | D18: 502320 | E18: 2699.4677 | F18: 0.019493088
A19: Mtar Technologies Limited | B19: INE864I01014 | C19: Aerospace & Defense | D19: 70409 | E19: 2680.3298 | F19: 0.019354892
... A43: Craftsman Automation Limited | B43: INE00LO01017 | C43: Auto Components | D43: 22153 | E43: 1667.2348 | F43: 0.012039246
A44: ICICI Prudential Asset Management Company Limited | B44: INE346A01027 | C44: Capital Markets | D44: 52308 | E44: 1627.8773 | F44: 0.011755042 | I44: 1052685 | J44: 945.20586 | K44: 0.012196634
A45: Hindustan Copper Limited | B45: INE531E01026 | C45: Non - Ferrous Metals | D45: 280786 | E45: 1590.0911 | F45: 0.011482185
A46: Solar Industries India Limited | B46: INE343H01029 | C46: Chemicals & Petrochemicals | D46: 11753 | E46: 1587.1251 | F46: 0.011460767
A47: Cemindia Projects Limited | B47: INE686A01026 | C47: Construction | D47: 272987 | E47: 1572.6781 | F47: 0.011356444
A48: Billionbrains Garage Ventures Limited | B48: INE0HOQ01053 | C48: Capital Markets | D48: 916201 | E48: 1497.897 | F48: 0.010816443
A49: Hindustan Zinc Limited | B49: INE267A01025 | C49: Non - Ferrous Metals | D49: 243530 | E49: 1470.4341 | F49: 0.010618131
A50: Narayana Hrudayalaya Ltd. | B50: INE410P01011 | C50: Healthcare Services | D50: 79632 | E50: 1457.9823 | F50: 0.010528215
A51: K.P.R. Mill Limited | B51: INE930H01031 | C51: Textiles & Apparels | D51: 158189 | E51: 1420.2208 | F51: 0.010255537
A52: Sansera Engineering Limited | B52: INE953O01021 | C52: Auto Components | D52: 60474 | E52: 1416.422 | F52: 0.010228105
A53: Thangamayil Jewellery Limited | B53: INE085J01014 | C53: Consumer Durables | D53: 35592 | E53: 1409.1585 | F53: 0.010175654
A54: CCL Products (India) Limited | B54: INE421D01022 | C54: Agricultural Food & other Products | D54: 127254 | E54: 1291.5645 | F54: 0.009326498
A55: Neuland Laboratories Limited | B55: INE794A01010 | C55: Pharmaceuticals & Biotechnology | D55: 9687 | E55: 1242.3577 | F55: 0.008971172 | I55: 27478 | J55: 749.75097 | K55: 0.0096745464
A56: Cholamandalam Financial Holdings Limited | B56: INE149A01033 | C56: Finance | D56: 75939 | E56: 1240.9192 | F56: 0.0089607841
A57: Healthcare Global Enterprises Limited | B57: INE075I01017 | C57: Healthcare Services | D57: 201974 | E57: 1162.6633 | F57: 0.0083956918
A58: Prudent Corporate Advisory Services Limited | B58: INE00F201020 | C58: Capital Markets | D58: 48579 | E58: 1141.5579 | F58: 0.0082432878
A59: PTC Industries Limited | B59: INE596F01018 | C59: Industrial Products | D59: 6290 | E59: 1128.1744 | F59: 0.0081466443
A60: Delhivery Limited | B60: INE148O01028 | C60: Transport Services | D60: 259661 | E60: 1125.3708 | F60: 0.008126399
A61: V2 Retail Limited | B61: INE945H01013 | C61: Retailing | D61: 52965 | E61: 1056.228 | F61: 0.0076271133
A62: Manappuram Finance Limited | B62: INE522D01027 | C62: Finance | D62: 369503 | E62: 1046.6172 | F62: 0.0075577131
A63: PNB Housing Finance Limited | B63: INE572E01012 | C63: Finance | D63: 126294 | E63: 1041.6098 | F63: 0.0075215536
A64: Central Depository Services (India) Limited | B64: INE736A01011 | C64: Capital Markets | D64: 80962 | E64: 1029.9986 | F64: 0.0074377081
...

Sheet TRUSTMF Multi Cap Fund
A1: ='TRUSTMF Small Cap Fund'!A1:H1 -> MONTHLY PORTFOLIO STATEMENT AS ON February 28, 2026
A2: [Pursuant to Regulation 59 A of Securities and Exchange Board of India (Mutual Funds)
A4: TRUSTMF MULTI CAP FUND (An open-ended equity scheme predominantly investing in multi cap stocks)
A5: Name of Instrument | B5: ISIN | C5: Rating/Industry | D5: Quantity | E5: Market Value (In Rs. lakh) | F5: % To Net Assets | G5: Yield to Maturity (YTM) | H5: Yield to Call (YTC) ^^
A6: Equity & Equity related | J6: s
A7: a) Listed / awaiting listing on Stock Exchanges
A8: State Bank of India | B8: INE062A01020 | C8: Banks | D8: 111591 | E8: 1340.989 | F8: 0.032483871
A9: HDFC Bank Limited | B9: INE040A01034 | C9: Banks | D9: 118875 | E9: 1055.3128 | F9: 0.025563702
A10: Axis Bank Limited | B10: INE238A01034 | C10: Banks | D10: 73796 | E10: 1021.2628 | F10: 0.024738882
A11: Karur Vysya Bank Limited | B11: INE036D01028 | C11: Banks | D11: 300480 | E11: 980.16576 | F11: 0.023743354
A12: Lenskart Solutions Limited | B12: INE956O01016 | C12: Retailing | D12: 174787 | E12: 939.30534 | F12: 0.022753559
A13: Max Financial Services Limited | B13: INE180A01020 | C13: Insurance | D13: 50604 | E13: 917.65294 | F13: 0.022229055
A14: ICICI Bank Limited | B14: INE090A01021 | C14: Banks | D14: 65444 | E14: 902.40732 | F14: 0.021859748
A15: Larsen & Toubro Limited | B15: INE018A01030 | C15: Construction | D15: 20512 | E15: 877.5649 | F15: 0.02125797
A16: Shriram Finance Limited | B16: INE721A01047 | C16: Finance | D16: 80846 | E16: 872.65172 | F16: 0.021138954
A17: Acutaas Chemicals Limited | B17: INE00FF01025 | C17: Pharmaceuticals & Biotechnology | D17: 39845 | E17: 860.17386 | F17: 0.020836692
A18: Reliance Industries Limited | B18: INE002A01018 | C18: Petroleum Products | D18: 60604 | E18: 844.75916 | F18: 0.020463289
A19: Bharat Electronics Limited | B19: INE263A01024 | C19: Aerospace & Defense | D19: 176761 | E19: 786.05617 | F19: 0.019041279
... A77: Pearl Global Industries Limited | B77: INE940H01022 | C77: Textiles & Apparels | D77: 12252 | E77: 188.53378 | F77: 0.0045670073
A78: Subtotal | E78: 38191.012 | F78: 0.92513201
A79: (b) UNLISTED
A80: Subtotal | E80: NIL | F80: NIL
A81: Total | E81: 38191.012 | F81: 0.92513201
A83: Debt Instruments
A84: (a) Listed / awaiting listing on Stock Exchange
A85: 6% Non-Convertible Redeemable Preference Shares (“NCRPS”) TVS Motor Company Limited # | B85: INE494B04019 | C85: CARE A1+ | D85: 49980 | E85: 5.13 | F85: 0.0001 | G85: 0.0633
A86: Subtotal | E86: =E85 -> 5.13 | F86: 0.0001
A87: (b) Privately placed / Unlisted
A88: Subtotal | E88: NIL | F88: NIL
A89: (c) Securitised Debt
A90: Subtotal | E90: NIL | F90: NIL
A91: Total | E91: =E86 -> 5.13 | F91: =F86 -> 0.0001
A93: Money Market Instruments
A94: Tri Party Repo (TREPs)
A95: TREPS | E95: 3058.8396 | F95: 0.074096765
A96: Subtotal | E96: 3058.8396 | F96: 0.074096765
A97: Total | E97: 3058.8396 | F97: 0.074096765
A99: Others
A100: Total | E100: NIL | F100: NIL
A102: Net Current Assets | E102: 26.703497 | F102: 0.00064686058
...

Sheet TRUSTMF Arbitrage Fund
A1: ='TRUSTMF Multi Cap Fund'!A1:H1 -> MONTHLY PORTFOLIO STATEMENT AS ON February 28, 2026
A2: [Pursuant to Regulation 59 A of Securities and Exchange Board of India (Mutual Funds)
A4: TRUSTMF ARBITRAGE FUND (An open-ended scheme investing in arbitrage opportunities)
A5: Name of Instrument | B5: ISIN | C5: Rating/Industry | D5: Quantity | E5: Market Value (In Rs. lakh) | F5: % To Net Assets | G5: Yield to Maturity (YTM) | H5: Yield to Call (YTC) ^^
A6: Equity & Equity related
A7: a) Listed / awaiting listing on Stock Exchanges
A8: HDFC Bank Limited | B8: INE040A01034 | C8: Banks | D8: 56100 | E8: 498.02775 | F8: 0.077802061
A9: Bandhan Bank Limited | B9: INE545U01014 | C9: Banks | D9: 216000 | E9: 393.0768 | F9: 0.061406588
A10: ICICI Bank Limited | B10: INE090A01021 | C10: Banks | D10: 24500 | E10: 337.8305 | F10: 0.052775993
A11: RBL Bank Limited | B11: INE976G01028 | C11: Banks | D11: 104775 | E11: 335.01806 | F11: 0.052336633
A12: Vodafone Idea Limited | B12: INE669E01016 | C12: Telecom - Services | D12: 2716050 | E12: 287.6297 | F12: 0.044933607
A13: Sammaan Capital Ltd. | B13: INE148I01020 | C13: Finance | D13: 167700 | E13: 251.39907 | F13: 0.039273646
A14: Bajaj Finance Limited | B14: INE296A01032 | C14: Finance | D14: 23250 | E14: 231.54675 | F14: 0.03617231
A15: Eternal Limited | B15: INE758T01015 | C15: Retailing | D15: 92150 | E15: 226.96545 | F15: 0.035456618
A16: Cholamandalam Investment & Finance Company Ltd | B16: INE121A01024 | C16: Finance | D16: 11875 | E16: 205.5325 | F16: 0.032108356
A17: NBCC (India) Limited | B17: INE095N01031 | C17: Construction | D17: 221000 | E17: 204.8007 | F17: 0.031994033
A18: ITC Limited | B18: INE154A01025 | C18: Diversified FMCG | D18: 44800 | E18: 140.4928 | F18: 0.021947832
A19: Crompton Greaves Consumer Electrical Ltd | B19: INE299U01018 | C19: Consumer Durables | D19: 52200 | E19: 134.5977 | F19: 0.021026897
... A40: NHPC Limited | B40: INE848E01016 | C40: Power | D40: 19200 | E40: 14.46336 | F40: 0.0022594709
A41: Subtotal | E41: 4535.1396 | F41: 0.70848102
A42: (b) UNLISTED
A43: Subtotal | E43: NIL | F43: NIL
A44: Total | E44: 4535.1396 | F44: 0.70848102
A45: Debt Instruments
A46: (a) Listed / awaiting listing on Stock Exchange
A47: Subtotal | E47: NIL | F47: NIL
A48: (b) Privately placed / Unlisted
A49: Subtotal | E49: NIL | F49: NIL
A50: (c) Securitised Debt
A51: Subtotal | E51: NIL | F51: NIL
A52: Total | E52: NIL | F52: NIL
A54: Money Market Instruments
A55: Tri Party Repo (TREPs)
A56: TREPS | E56: 102.1163 | F56: 0.015952642
A57: Subtotal | E57: 102.1163 | F57: 0.015952642
A58: Total | E58: 102.1163 | F58: 0.015952642
A60: Others
A61: Total | E61: NIL | F61: NIL
A63: Net Current Assets | E63: 1763.9595 | F63: 0.27556633
A64: GRAND TOTAL | E64: 6401.2154 | F64: 1
...

Sheet XDO_METADATA
A1: Version
A2: ARU-dbdrv
A3: Extractor Version
A4: Template Code
A5: Template Type | B5: TYPE_EXCEL_TEMPLATE
A6: Preprocess XSLT File
A7: Last Modified Date
A8: Last Modified By
A10: Data Constraints:
A11: XDO_SHEET_? | B11: <?.//G_2?>
A12: XDO_SHEET_NAME_? | B12: <?FUND?> | C12: <?Sheet1?>
